<?xml version="1.0" encoding="utf-8"?>
<!-- This URDF was automatically created by SolidWorks to URDF Exporter! Originally created by Stephen Brawner (brawner@gmail.com) 
     Commit Version: 1.6.0-4-g7f85cfe  Build Version: 1.6.7995.38578
     For more information, please see http://wiki.ros.org/sw_urdf_exporter -->
<robot
  name="wheel_dual_arm_robot">
  <link
    name="base_link">
    <inertial>
      <origin
        xyz="-0.0201415805291187 0.0500230273876207 -0.00221557030378681"
        rpy="0 0 0" />
      <mass
        value="6.86209526220681" />
      <inertia
        ixx="0.27557036960768"
        ixy="0.00743392438385733"
        ixz="0.000246464894421617"
        iyy="0.308475312332188"
        iyz="-0.000540704721416503"
        izz="0.116604332994802" />
    </inertial>
    <visual>
      <origin
        xyz="0 0 0"
        rpy="0 0 0" />
      <geometry>
        <mesh
          filename="package://wheel_dual_arm_robot/meshes/base_link.STL" />
      </geometry>
      <material
        name="">
        <color
          rgba="0.792156862745098 0.819607843137255 0.933333333333333 1" />
      </material>
    </visual>
    <collision>
      <origin
        xyz="0 0 0"
        rpy="0 0 0" />
      <geometry>
        <mesh
          filename="package://wheel_dual_arm_robot/meshes/base_link.STL" />
      </geometry>
    </collision>
  </link>
  <link
    name="b-l1">
    <inertial>
      <origin
        xyz="0.188027704122708 -0.0109031872351374 -0.00332452504895082"
        rpy="0 0 0" />
      <mass
        value="3.30257766952345" />
      <inertia
        ixx="0.00989570457379286"
        ixy="-6.36219474638752E-06"
        ixz="3.51041289548419E-05"
        iyy="0.0503821756135365"
        iyz="3.73833691425185E-07"
        izz="0.0550369035736467" />
    </inertial>
    <visual>
      <origin
        xyz="0 0 0"
        rpy="0 0 0" />
      <geometry>
        <mesh
          filename="package://wheel_dual_arm_robot/meshes/b-l1.STL" />
      </geometry>
      <material
        name="">
        <color
          rgba="0.792156862745098 0.819607843137255 0.933333333333333 1" />
      </material>
    </visual>
    <collision>
      <origin
        xyz="0 0 0"
        rpy="0 0 0" />
      <geometry>
        <mesh
          filename="package://wheel_dual_arm_robot/meshes/b-l1.STL" />
      </geometry>
    </collision>
  </link>
  <joint
    name="b-j1"
    type="revolute">
    <origin
      xyz="0.03 0 0.131"
      rpy="-1.5708 -1.5708 0" />
    <parent
      link="base_link" />
    <child
      link="b-l1" />
    <axis
      xyz="0 0 -1" />
    <limit
      lower="-3.1416"
      upper="3.1416"
      effort="0"
      velocity="0" />
  </joint>
  <link
    name="b-l2">
    <inertial>
      <origin
        xyz="0.236712922238934 0.00496419456824127 5.09644711322456E-07"
        rpy="0 0 0" />
      <mass
        value="4.33563046644472" />
      <inertia
        ixx="0.0128816448157487"
        ixy="0.00295524022331279"
        ixz="8.51205640385731E-09"
        iyy="0.0475589361496227"
        iyz="-4.98704408267107E-09"
        izz="0.0559120043479514" />
    </inertial>
    <visual>
      <origin
        xyz="0 0 0"
        rpy="0 0 0" />
      <geometry>
        <mesh
          filename="package://wheel_dual_arm_robot/meshes/b-l2.STL" />
      </geometry>
      <material
        name="">
        <color
          rgba="0.792156862745098 0.819607843137255 0.933333333333333 1" />
      </material>
    </visual>
    <collision>
      <origin
        xyz="0 0 0"
        rpy="0 0 0" />
      <geometry>
        <mesh
          filename="package://wheel_dual_arm_robot/meshes/b-l2.STL" />
      </geometry>
    </collision>
  </link>
  <joint
    name="b-j2"
    type="revolute">
    <origin
      xyz="0.35 0 0"
      rpy="0 0 0" />
    <parent
      link="b-l1" />
    <child
      link="b-l2" />
    <axis
      xyz="0 0 -1" />
    <limit
      lower="-3.1416"
      upper="3.1416"
      effort="0"
      velocity="0" />
  </joint>
  <link
    name="b-l3">
    <inertial>
      <origin
        xyz="0.346657922816514 0.00663376861106405 0.000184783506477361"
        rpy="0 0 0" />
      <mass
        value="5.27028256939189" />
      <inertia
        ixx="0.0307244057335929"
        ixy="-0.000812015826494931"
        ixz="-3.97322712465808E-05"
        iyy="0.0563093617977367"
        iyz="8.66097148199001E-06"
        izz="0.0403075388576739" />
    </inertial>
    <visual>
      <origin
        xyz="0 0 0"
        rpy="0 0 0" />
      <geometry>
        <mesh
          filename="package://wheel_dual_arm_robot/meshes/b-l3.STL" />
      </geometry>
      <material
        name="">
        <color
          rgba="0.792156862745098 0.819607843137255 0.933333333333333 1" />
      </material>
    </visual>
    <collision>
      <origin
        xyz="0 0 0"
        rpy="0 0 0" />
      <geometry>
        <mesh
          filename="package://wheel_dual_arm_robot/meshes/b-l3.STL" />
      </geometry>
    </collision>
  </link>
  <joint
    name="b-j3"
    type="revolute">
    <origin
      xyz="0.35 0 0"
      rpy="0 0 0" />
    <parent
      link="b-l2" />
    <child
      link="b-l3" />
    <axis
      xyz="0 0 -1" />
    <limit
      lower="-3.1416"
      upper="3.1416"
      effort="0"
      velocity="0" />
  </joint>
  <link
    name="base_arm_link">
    <inertial>
      <origin
        xyz="-1.84227633148737E-15 7.66216954968322E-14 1.91174448080922E-05"
        rpy="0 0 0" />
      <mass
        value="1.88365700165481" />
      <inertia
        ixx="0.00336864771403572"
        ixy="3.54413307826074E-06"
        ixz="-3.41040500397664E-17"
        iyy="0.00262584899105153"
        iyz="6.24660731309671E-15"
        izz="0.00326368725574852" />
    </inertial>
    <visual>
      <origin
        xyz="0 0 0"
        rpy="0 0 0" />
      <geometry>
        <mesh
          filename="package://wheel_dual_arm_robot/meshes/base_arm_link.STL" />
      </geometry>
      <material
        name="">
        <color
          rgba="0.792156862745098 0.819607843137255 0.933333333333333 1" />
      </material>
    </visual>
    <collision>
      <origin
        xyz="0 0 0"
        rpy="0 0 0" />
      <geometry>
        <mesh
          filename="package://wheel_dual_arm_robot/meshes/base_arm_link.STL" />
      </geometry>
    </collision>
  </link>
  <joint
    name="base_arm-j0"
    type="fixed">
    <origin
      xyz="0.454 0 0"
      rpy="1.5708 0 1.5708" />
    <parent
      link="b-l3" />
    <child
      link="base_arm_link" />
    <axis
      xyz="0 0 0" />
  </joint>
</robot>