<?xml version="1.0" encoding="utf-8"?>
<!-- This URDF was automatically created by SolidWorks to URDF Exporter! Originally created by Stephen Brawner (brawner@gmail.com) 
     Commit Version: 1.6.0-4-g7f85cfe  Build Version: 1.6.7995.38578
     For more information, please see http://wiki.ros.org/sw_urdf_exporter -->
<robot
  name="wheel_dual_arm_robot">
  <link
    name="base_link">
    <inertial>
      <origin
        xyz="-0.0201415828038005 0.00221556792021169 0.0500230258420477"
        rpy="0 0 0" />
      <mass
        value="6.86209515901701" />
      <inertia
        ixx="0.275570365325153"
        ixy="-0.000246465901288815"
        ixz="0.00743392369500423"
        iyy="0.116604331209899"
        iyz="0.00054070674314701"
        izz="0.308475309095619" />
    </inertial>
    <visual>
      <origin
        xyz="0 0 0"
        rpy="0 0 0" />
      <geometry>
        <mesh
          filename="package://wheel_dual_arm_robot/meshes/base_link.STL" />
      </geometry>
      <material
        name="">
        <color
          rgba="0.792156862745098 0.819607843137255 0.933333333333333 1" />
      </material>
    </visual>
    <collision>
      <origin
        xyz="0 0 0"
        rpy="0 0 0" />
      <geometry>
        <mesh
          filename="package://wheel_dual_arm_robot/meshes/base_link.STL" />
      </geometry>
    </collision>
  </link>
  <link
    name="b1">
    <inertial>
      <origin
        xyz="0.188027704122708 -0.0109031872351374 -0.00332452504895085"
        rpy="0 0 0" />
      <mass
        value="3.30257766952345" />
      <inertia
        ixx="0.00989570457379286"
        ixy="-6.36219474638727E-06"
        ixz="3.51041289548418E-05"
        iyy="0.0503821756135365"
        iyz="3.73833691425161E-07"
        izz="0.0550369035736467" />
    </inertial>
    <visual>
      <origin
        xyz="0 0 0"
        rpy="0 0 0" />
      <geometry>
        <mesh
          filename="package://wheel_dual_arm_robot/meshes/b1.STL" />
      </geometry>
      <material
        name="">
        <color
          rgba="0.792156862745098 0.819607843137255 0.933333333333333 1" />
      </material>
    </visual>
    <collision>
      <origin
        xyz="0 0 0"
        rpy="0 0 0" />
      <geometry>
        <mesh
          filename="package://wheel_dual_arm_robot/meshes/b1.STL" />
      </geometry>
    </collision>
  </link>
  <joint
    name="b-j1"
    type="revolute">
    <origin
      xyz="0.03 0 0.131"
      rpy="-1.5708 -1.5708 0" />
    <parent
      link="base_link" />
    <child
      link="b1" />
    <axis
      xyz="0 0 -1" />
    <limit
      lower="-6.2832"
      upper="6.2832"
      effort="0"
      velocity="0" />
  </joint>
  <link
    name="b2">
    <inertial>
      <origin
        xyz="0.236712922238933 0.00496419456824126 5.09644711311167E-07"
        rpy="0 0 0" />
      <mass
        value="4.33563046644472" />
      <inertia
        ixx="0.0128816448157487"
        ixy="0.0029552402233128"
        ixz="8.51205640355921E-09"
        iyy="0.0475589361496227"
        iyz="-4.9870440824138E-09"
        izz="0.0559120043479514" />
    </inertial>
    <visual>
      <origin
        xyz="0 0 0"
        rpy="0 0 0" />
      <geometry>
        <mesh
          filename="package://wheel_dual_arm_robot/meshes/b2.STL" />
      </geometry>
      <material
        name="">
        <color
          rgba="0.792156862745098 0.819607843137255 0.933333333333333 1" />
      </material>
    </visual>
    <collision>
      <origin
        xyz="0 0 0"
        rpy="0 0 0" />
      <geometry>
        <mesh
          filename="package://wheel_dual_arm_robot/meshes/b2.STL" />
      </geometry>
    </collision>
  </link>
  <joint
    name="b-j2"
    type="revolute">
    <origin
      xyz="0.35 0 0"
      rpy="0 0 0" />
    <parent
      link="b1" />
    <child
      link="b2" />
    <axis
      xyz="0 0 -1" />
    <limit
      lower="-6.2832"
      upper="6.2832"
      effort="0"
      velocity="0" />
  </joint>
  <link
    name="b3">
    <inertial>
      <origin
        xyz="0.34666 0.0066338 0.00018478"
        rpy="0 0 0" />
      <mass
        value="5.2703" />
      <inertia
        ixx="0.030724"
        ixy="-0.00081202"
        ixz="-3.9732E-05"
        iyy="0.056309"
        iyz="8.6606E-06"
        izz="0.040308" />
    </inertial>
    <visual>
      <origin
        xyz="0 0 0"
        rpy="0 0 0" />
      <geometry>
        <mesh
          filename="package://wheel_dual_arm_robot/meshes/b3.STL" />
      </geometry>
      <material
        name="">
        <color
          rgba="0.79216 0.81961 0.93333 1" />
      </material>
    </visual>
    <collision>
      <origin
        xyz="0 0 0"
        rpy="0 0 0" />
      <geometry>
        <mesh
          filename="package://wheel_dual_arm_robot/meshes/b3.STL" />
      </geometry>
    </collision>
  </link>
  <joint
    name="b-j3"
    type="revolute">
    <origin
      xyz="0.35 0 0"
      rpy="0 0 0" />
    <parent
      link="b2" />
    <child
      link="b3" />
    <axis
      xyz="0 0 -1" />
    <limit
      lower="-6.2832"
      upper="6.2832"
      effort="0"
      velocity="0" />
  </joint>
  <link
    name="arm_base_link">
    <inertial>
      <origin
        xyz="-6.7654E-16 7.6585E-14 1.9117E-05"
        rpy="0 0 0" />
      <mass
        value="1.8837" />
      <inertia
        ixx="0.0033686"
        ixy="3.5441E-06"
        ixz="-1.8863E-17"
        iyy="0.0026258"
        iyz="3.4975E-15"
        izz="0.0032637" />
    </inertial>
    <visual>
      <origin
        xyz="0 0 0"
        rpy="0 0 0" />
      <geometry>
        <mesh
          filename="package://wheel_dual_arm_robot/meshes/arm_base_link.STL" />
      </geometry>
      <material
        name="">
        <color
          rgba="0.79216 0.81961 0.93333 1" />
      </material>
    </visual>
    <collision>
      <origin
        xyz="0 0 0"
        rpy="0 0 0" />
      <geometry>
        <mesh
          filename="package://wheel_dual_arm_robot/meshes/arm_base_link.STL" />
      </geometry>
    </collision>
  </link>
  <joint
    name="body_to_arm"
    type="fixed">
    <origin
      xyz="0.454 0 0"
      rpy="1.5708 0 1.5708" />
    <parent
      link="b3" />
    <child
      link="arm_base_link" />
    <axis
      xyz="0 0 0" />
  </joint>
  <link
    name="l1">
    <inertial>
      <origin
        xyz="4.7935E-07 3.2897E-08 -0.043212"
        rpy="0 0 0" />
      <mass
        value="0.53062" />
      <inertia
        ixx="0.0010889"
        ixy="-2.4647E-09"
        ixz="-2.6799E-09"
        iyy="0.0013466"
        iyz="-8.9774E-10"
        izz="0.00075651" />
    </inertial>
    <visual>
      <origin
        xyz="0 0 0"
        rpy="0 0 0" />
      <geometry>
        <mesh
          filename="package://wheel_dual_arm_robot/meshes/l1.STL" />
      </geometry>
      <material
        name="">
        <color
          rgba="0.79216 0.81961 0.93333 1" />
      </material>
    </visual>
    <collision>
      <origin
        xyz="0 0 0"
        rpy="0 0 0" />
      <geometry>
        <mesh
          filename="package://wheel_dual_arm_robot/meshes/l1.STL" />
      </geometry>
    </collision>
  </link>
  <joint
    name="l-j1"
    type="revolute">
    <origin
      xyz="0 0.225 0"
      rpy="-1.5708 1.5708 0" />
    <parent
      link="arm_base_link" />
    <child
      link="l1" />
    <axis
      xyz="0 0 1" />
    <limit
      lower="-6.2832"
      upper="6.2832"
      effort="0"
      velocity="0" />
  </joint>
  <link
    name="r1">
    <inertial>
      <origin
        xyz="-4.7935E-07 -3.2897E-08 -0.043212"
        rpy="0 0 0" />
      <mass
        value="0.53062" />
      <inertia
        ixx="0.0010889"
        ixy="-2.4647E-09"
        ixz="2.6799E-09"
        iyy="0.0013466"
        iyz="8.9774E-10"
        izz="0.00075651" />
    </inertial>
    <visual>
      <origin
        xyz="0 0 0"
        rpy="0 0 0" />
      <geometry>
        <mesh
          filename="package://wheel_dual_arm_robot/meshes/r1.STL" />
      </geometry>
      <material
        name="">
        <color
          rgba="0.79216 0.81961 0.93333 1" />
      </material>
    </visual>
    <collision>
      <origin
        xyz="0 0 0"
        rpy="0 0 0" />
      <geometry>
        <mesh
          filename="package://wheel_dual_arm_robot/meshes/r1.STL" />
      </geometry>
    </collision>
  </link>
  <joint
    name="r-j1"
    type="revolute">
    <origin
      xyz="0 -0.225 0"
      rpy="1.5708 -1.5708 0" />
    <parent
      link="arm_base_link" />
    <child
      link="r1" />
    <axis
      xyz="0 0 1" />
    <limit
      lower="-6.2832"
      upper="6.2832"
      effort="0"
      velocity="0" />
  </joint>
</robot>