<?xml version="1.0" encoding="utf-8"?>
<!-- This URDF was automatically created by SolidWorks to URDF Exporter! Originally created by Stephen Brawner (brawner@gmail.com) 
     Commit Version: 1.6.0-4-g7f85cfe  Build Version: 1.6.7995.38578
     For more information, please see http://wiki.ros.org/sw_urdf_exporter -->
<robot
  name="wheel_dual_arm_robot">
  <link
    name="base_link">
    <inertial>
      <origin
        xyz="-0.020142 0.0022156 0.050023"
        rpy="0 0 0" />
      <mass
        value="6.8621" />
      <inertia
        ixx="0.27557"
        ixy="-0.00024647"
        ixz="0.0074339"
        iyy="0.1166"
        iyz="0.00054071"
        izz="0.30848" />
    </inertial>
    <visual>
      <origin
        xyz="0 0 0"
        rpy="0 0 0" />
      <geometry>
        <mesh
          filename="package://wheel_dual_arm_robot/meshes/base_link.STL" />
      </geometry>
      <material
        name="">
        <color
          rgba="0.79216 0.81961 0.93333 1" />
      </material>
    </visual>
    <collision>
      <origin
        xyz="0 0 0"
        rpy="0 0 0" />
      <geometry>
        <mesh
          filename="package://wheel_dual_arm_robot/meshes/base_link.STL" />
      </geometry>
    </collision>
  </link>
  <link
    name="b-l1">
    <inertial>
      <origin
        xyz="0.18803 -0.010903 -0.0033245"
        rpy="0 0 0" />
      <mass
        value="3.3026" />
      <inertia
        ixx="0.0098957"
        ixy="-6.3622E-06"
        ixz="3.5104E-05"
        iyy="0.050382"
        iyz="3.7383E-07"
        izz="0.055037" />
    </inertial>
    <visual>
      <origin
        xyz="0 0 0"
        rpy="0 0 0" />
      <geometry>
        <mesh
          filename="package://wheel_dual_arm_robot/meshes/b-l1.STL" />
      </geometry>
      <material
        name="">
        <color
          rgba="0.79216 0.81961 0.93333 1" />
      </material>
    </visual>
    <collision>
      <origin
        xyz="0 0 0"
        rpy="0 0 0" />
      <geometry>
        <mesh
          filename="package://wheel_dual_arm_robot/meshes/b-l1.STL" />
      </geometry>
    </collision>
  </link>
  <joint
    name="b-j1"
    type="revolute">
    <origin
      xyz="0.03 0 0.131"
      rpy="-1.5708 -1.5708 0" />
    <parent
      link="base_link" />
    <child
      link="b-l1" />
    <axis
      xyz="0 0 -1" />
    <limit
      lower="-3.1416"
      upper="3.1416"
      effort="0"
      velocity="0" />
  </joint>
  <link
    name="b-l2">
    <inertial>
      <origin
        xyz="0.23671 0.0049642 5.0964E-07"
        rpy="0 0 0" />
      <mass
        value="4.3356" />
      <inertia
        ixx="0.012882"
        ixy="0.0029552"
        ixz="8.5121E-09"
        iyy="0.047559"
        iyz="-4.987E-09"
        izz="0.055912" />
    </inertial>
    <visual>
      <origin
        xyz="0 0 0"
        rpy="0 0 0" />
      <geometry>
        <mesh
          filename="package://wheel_dual_arm_robot/meshes/b-l2.STL" />
      </geometry>
      <material
        name="">
        <color
          rgba="0.79216 0.81961 0.93333 1" />
      </material>
    </visual>
    <collision>
      <origin
        xyz="0 0 0"
        rpy="0 0 0" />
      <geometry>
        <mesh
          filename="package://wheel_dual_arm_robot/meshes/b-l2.STL" />
      </geometry>
    </collision>
  </link>
  <joint
    name="b-j2"
    type="revolute">
    <origin
      xyz="0.35 0 0"
      rpy="0 0 0" />
    <parent
      link="b-l1" />
    <child
      link="b-l2" />
    <axis
      xyz="0 0 -1" />
    <limit
      lower="-3.1416"
      upper="3.1416"
      effort="0"
      velocity="0" />
  </joint>
  <link
    name="b-l3">
    <inertial>
      <origin
        xyz="0.34666 0.0066338 0.00018478"
        rpy="0 0 0" />
      <mass
        value="5.2703" />
      <inertia
        ixx="0.030724"
        ixy="-0.00081202"
        ixz="-3.9734E-05"
        iyy="0.056309"
        iyz="8.6604E-06"
        izz="0.040308" />
    </inertial>
    <visual>
      <origin
        xyz="0 0 0"
        rpy="0 0 0" />
      <geometry>
        <mesh
          filename="package://wheel_dual_arm_robot/meshes/b-l3.STL" />
      </geometry>
      <material
        name="">
        <color
          rgba="0.79216 0.81961 0.93333 1" />
      </material>
    </visual>
    <collision>
      <origin
        xyz="0 0 0"
        rpy="0 0 0" />
      <geometry>
        <mesh
          filename="package://wheel_dual_arm_robot/meshes/b-l3.STL" />
      </geometry>
    </collision>
  </link>
  <joint
    name="b-j3"
    type="revolute">
    <origin
      xyz="0.35 0 0"
      rpy="0 0 0" />
    <parent
      link="b-l2" />
    <child
      link="b-l3" />
    <axis
      xyz="0 0 -1" />
    <limit
      lower="-3.1416"
      upper="3.1416"
      effort="0"
      velocity="0" />
  </joint>
  <link
    name="base_arm_link">
    <inertial>
      <origin
        xyz="0 2.41719608755602E-19 -2.22044604925031E-16"
        rpy="0 0 0" />
      <mass
        value="0.00425983303776923" />
      <inertia
        ixx="1.79901301092426E-07"
        ixy="2.60065130219171E-23"
        ixz="7.37569379528619E-24"
        iyy="2.88805384888699E-07"
        iyz="-1.27666631849911E-19"
        izz="1.79901301092426E-07" />
    </inertial>
    <visual>
      <origin
        xyz="0 0 0"
        rpy="0 0 0" />
      <geometry>
        <mesh
          filename="package://wheel_dual_arm_robot/meshes/base_arm_link.STL" />
      </geometry>
      <material
        name="">
        <color
          rgba="1 1 1 1" />
      </material>
    </visual>
    <collision>
      <origin
        xyz="0 0 0"
        rpy="0 0 0" />
      <geometry>
        <mesh
          filename="package://wheel_dual_arm_robot/meshes/base_arm_link.STL" />
      </geometry>
    </collision>
  </link>
  <joint
    name="base_arm-j0"
    type="fixed">
    <origin
      xyz="0.454 0 0"
      rpy="1.5708 0 1.5708" />
    <parent
      link="b-l3" />
    <child
      link="base_arm_link" />
    <axis
      xyz="0 0 0" />
  </joint>
</robot>